Workbook
Name QBCANSUPPORTUPDATE: TRUE
Name QBCOMPANYFILENAME: "C:\Users\17782\Desktop\$$Data Files\$QuickBooks Files\$Russell Mcmann Companies QB\McMann Group Inc\McMann Group Inc.QBW"
Name QBHEADERSONSCREEN: FALSE
Name QBMETADATASIZE: 8049
Name QBPRESERVECOLOR: TRUE
Name QBPRESERVEFONT: TRUE
Name QBPRESERVEROWHEIGHT: TRUE
Name QBPRESERVESPACE: TRUE
Name QBREPORTCOLAXIS: 0
Name QBREPORTCOMPANYID: "cdb3831d65524c189c285e069069d325"
Name QBREPORTCOMPARECOL_ANNUALBUDGET: FALSE
Name QBREPORTCOMPARECOL_AVGCOGS: FALSE
Name QBREPORTCOMPARECOL_AVGPRICE: FALSE
Name QBREPORTCOMPARECOL_BUDDIFF: FALSE
Name QBREPORTCOMPARECOL_BUDGET: FALSE
Name QBREPORTCOMPARECOL_BUDPCT: FALSE
Name QBREPORTCOMPARECOL_COGS: FALSE
Name QBREPORTCOMPARECOL_EXCLUDEAMOUNT: FALSE
Name QBREPORTCOMPARECOL_EXCLUDECURPERIOD: FALSE
Name QBREPORTCOMPARECOL_FORECAST: FALSE
Name QBREPORTCOMPARECOL_GROSSMARGIN: FALSE
Name QBREPORTCOMPARECOL_GROSSMARGINPCT: FALSE
Name QBREPORTCOMPARECOL_HOURS: FALSE
Name QBREPORTCOMPARECOL_PCTCOL: FALSE
Name QBREPORTCOMPARECOL_PCTEXPENSE: FALSE
Name QBREPORTCOMPARECOL_PCTINCOME: FALSE
Name QBREPORTCOMPARECOL_PCTOFSALES: FALSE
Name QBREPORTCOMPARECOL_PCTROW: FALSE
Name QBREPORTCOMPARECOL_PPDIFF: FALSE
Name QBREPORTCOMPARECOL_PPPCT: FALSE
Name QBREPORTCOMPARECOL_PREVPERIOD: FALSE
Name QBREPORTCOMPARECOL_PREVYEAR: FALSE
Name QBREPORTCOMPARECOL_PYDIFF: FALSE
Name QBREPORTCOMPARECOL_PYPCT: FALSE
Name QBREPORTCOMPARECOL_QTY: FALSE
Name QBREPORTCOMPARECOL_RATE: FALSE
Name QBREPORTCOMPARECOL_TRIPBILLEDMILES: FALSE
Name QBREPORTCOMPARECOL_TRIPBILLINGAMOUNT: FALSE
Name QBREPORTCOMPARECOL_TRIPMILES: FALSE
Name QBREPORTCOMPARECOL_TRIPNOTBILLABLEMILES: FALSE
Name QBREPORTCOMPARECOL_TRIPTAXDEDUCTIBLEAMOUNT: FALSE
Name QBREPORTCOMPARECOL_TRIPUNBILLEDMILES: FALSE
Name QBREPORTCOMPARECOL_YTD: FALSE
Name QBREPORTCOMPARECOL_YTDBUDGET: FALSE
Name QBREPORTCOMPARECOL_YTDPCT: FALSE
Name QBREPORTROWAXIS: 15
Name QBREPORTSUBCOLAXIS: 0
Name QBREPORTTYPE: 109
Name QBROWHEADERS: 2

Sheet Cost Breakdown
A2: LINE ITEM | B2: BUDGET | C2: Prev. Invoiced | D2: CURRENT INVOICE | E2: TOTAL INVOICED | F2: TO BE COMPLETED | G2: OVER BUDGET | H2: CHANGE ORDERS
A4: DESIGN SERVICES
A5: Plan Desgin | B5: 17850 | D5: =SUMIF(Material!$E:$E,TRIM(A5),Material!$F:$F) -> 9246.3 | E5: =SUM(C5:D5) -> 9246.3 | F5: =IF(AND(B5>0,B5>E5),B5-E5,0) -> 8603.7 | G5: =IF(AND(B5>0,B5<E5),B5-E5,0) -> 0 | H5: =IF(AND(B5=0,B5<E5),E5-B5,0) -> 0
A6: Plan Printing & Photocopying | B6: 525 | D6: =SUMIF(Material!$E:$E,TRIM(A6),Material!$F:$F) -> 158.93 | E6: =SUM(C6:D6) -> 158.93 | F6: =IF(AND(B6>0,B6>E6),B6-E6,0) -> 366.07 | G6: =IF(AND(B6>0,B6<E6),B6-E6,0) -> 0 | H6: 0
A7: DESIGN SERVICES — Subtotal | B7: =SUM(B5:B6) -> 18375 | C7: =SUM(C5:C6) -> 0 | D7: =SUM(D5:D6) -> 9405.23 | E7: =SUM(E5:E6) -> 9405.23 | F7: =SUM(F5:F6) -> 8969.77 | G7: =SUM(G5:G6) -> 0 | H7: =SUM(H5:H6) -> 0
A9: PERMITS & HOME WARRANTY
A10: Building Permit Fees | B10: 10500 | D10: =SUMIF(Material!$E:$E,TRIM(A10),Material!$F:$F) -> 8216.35 | E10: =SUM(C10:D10) -> 8216.35 | F10: =IF(AND(B10>0,B10>E10),B10-E10,0) -> 2283.65 | G10: =IF(AND(B10>0,B10<E10),B10-E10,0) -> 0 | H10: =IF(AND(B10=0,B10<E10),E10-B10,0) -> 0
A11: Home Warranty Registration & Fees | B11: 2100 | D11: =SUMIF(Material!$E:$E,TRIM(A11),Material!$F:$F) -> 1250 | E11: =SUM(C11:D11) -> 1250 | F11: =IF(AND(B11>0,B11>E11),B11-E11,0) -> 850 | G11: =IF(AND(B11>0,B11<E11),B11-E11,0) -> 0 | H11: 0
A12: BC Housing Registration Fee | B12: 42 | D12: =SUMIF(Material!$E:$E,TRIM(A12),Material!$F:$F) -> 40 | E12: =SUM(C12:D12) -> 40 | F12: =IF(AND(B12>0,B12>E12),B12-E12,0) -> 2 | G12: =IF(AND(B12>0,B12<E12),B12-E12,0) -> 0 | H12: =IF(AND(B12=0,B12<E12),E12-B12,0) -> 0
A13: DCC Fees | B13: 10500 | D13: =SUMIF(Material!$E:$E,TRIM(A13),Material!$F:$F) -> 0 | E13: =SUM(C13:D13) -> 0 | F13: =IF(AND(B13>0,B13>E13),B13-E13,0) -> 10500 | G13: =IF(AND(B13>0,B13<E13),B13-E13,0) -> 0 | H13: 0
A14: PERMITS & HOME WARRANTY — Subtotal | B14: =SUM(B10:B13) -> 23142 | C14: =SUM(C10:C13) -> 0 | D14: =SUM(D10:D13) -> 9506.35 | E14: =SUM(E10:E13) -> 9506.35 | F14: =SUM(F10:F13) -> 13635.65 | G14: =SUM(G10:G13) -> 0 | H14: =SUM(H10:H13) -> 0
A16: ENGINEERING FEES
A17: Energy Advisor | B17: 1575 | D17: =SUMIF(Material!$E:$E,TRIM(A17),Material!$F:$F) -> 918.75 | E17: =SUM(C17:D17) -> 918.75 | F17: =IF(AND(B17>0,B17>E17),B17-E17,0) -> 656.25 | G17: =IF(AND(B17>0,B17<E17),B17-E17,0) -> 0 | H17: =IF(AND(B17=0,B17<E17),E17-B17,0) -> 0
A18: Land Survey | B18: 8400 | D18: =SUMIF(Material!$E:$E,TRIM(A18),Material!$F:$F) -> 8035.13 | E18: =SUM(C18:D18) -> 8035.13 | F18: =IF(AND(B18>0,B18>E18),B18-E18,0) -> 364.87 | G18: =IF(AND(B18>0,B18<E18),B18-E18,0) -> 0 | H18: =IF(AND(B18=0,B18<E18),E18-B18,0) -> 0
A19: Geotechnical Engineering | B19: 2100 | D19: =SUMIF(Material!$E:$E,TRIM(A19),Material!$F:$F) -> 883.68 | E19: =SUM(C19:D19) -> 883.68 | F19: =IF(AND(B19>0,B19>E19),B19-E19,0) -> 1216.32 | G19: =IF(AND(B19>0,B19<E19),B19-E19,0) -> 0 | H19: =IF(AND(B19=0,B19<E19),E19-B19,0) -> 0
A20: Structural Engineering | B20: 7350 | D20: =SUMIF(Material!$E:$E,TRIM(A20),Material!$F:$F) -> 7849.17 | E20: =SUM(C20:D20) -> 7849.17 | F20: =IF(AND(B20>0,B20>E20),B20-E20,0) -> 0 | G20: =IF(AND(B20>0,B20<E20),B20-E20,0) -> -499.17 | H20: =IF(AND(B20=0,B20<E20),E20-B20,0) -> 0
A21: ENGINEERING FEES — Subtotal | B21: =SUM(B17:B20) -> 19425 | C21: =SUM(C17:C20) -> 0 | D21: =SUM(D17:D20) -> 17686.73 | E21: =SUM(E17:E20) -> 17686.73 | F21: =SUM(F17:F20) -> 2237.44 | G21: =SUM(G17:G20) -> -499.17 | H21: =SUM(H17:H20) -> 0
A23: SITE WORK
A24: Backfill, Perimeter & Drain Material | B24: 21000 | D24: =SUMIF(Material!$E:$E,TRIM(A24),Material!$F:$F) -> 25071.19 | E24: =SUM(C24:D24) -> 25071.19 | F24: =IF(AND(B24>0,B24>E24),B24-E24,0) -> 0 | G24: =IF(AND(B24>0,B24<E24),B24-E24,0) -> -4071.19 | H24: =IF(AND(B24=0,B24<E24),E24-B24,0) -> 0
A25: Excavation, Backfill, Perimeter & Drain Labour | B25: 21000 | D25: =SUMIF(Material!$E:$E,TRIM(A25),Material!$F:$F) -> 59319.02 | E25: =SUM(C25:D25) -> 59319.02 | F25: =IF(AND(B25>0,B25>E25),B25-E25,0) -> 0 | G25: =IF(AND(B25>0,B25<E25),B25-E25,0) -> -38319.02 | H25: =IF(AND(B25=0,B25<E25),E25-B25,0) -> 0
A26: Septic | B26: 26250 | D26: =SUMIF(Material!$E:$E,TRIM(A26),Material!$F:$F) -> 1795.5 | E26: =SUM(C26:D26) -> 1795.5 | F26: =IF(AND(B26>0,B26>E26),B26-E26,0) -> 24454.5 | G26: =IF(AND(B26>0,B26<E26),B26-E26,0) -> 0 | H26: =IF(AND(B26=0,B26<E26),E26-B26,0) -> 0
A27: SITE WORK — Subtotal | B27: =SUM(B24:B26) -> 68250 | C27: =SUM(C24:C26) -> 0 | D27: =SUM(D24:D26) -> 86185.71 | E27: =SUM(E24:E26) -> 86185.71 | F27: =SUM(F24:F26) -> 24454.5 | G27: =SUM(G24:G26) -> -42390.21 | H27: =SUM(H24:H26) -> 0
A29: FOUNDATION
A30: Footings and Foundation Material | B30: 8597.5365 | D30: =SUMIF(Material!$E:$E,TRIM(A30),Material!$F:$F) -> 16250.66 | E30: =SUM(C30:D30) -> 16250.66 | F30: =IF(AND(B30>0,B30>E30),B30-E30,0) -> 0 | G30: =IF(AND(B30>0,B30<E30),B30-E30,0) -> -7653.1235 | H30: =IF(AND(B30=0,B30<E30),E30-B30,0) -> 0
A31: Foundation & Footings concrete | B31: 28140 | D31: =SUMIF(Material!$E:$E,TRIM(A31),Material!$F:$F) -> 23549.78 | E31: =SUM(C31:D31) -> 23549.78 | F31: =IF(AND(B31>0,B31>E31),B31-E31,0) -> 4590.22 | G31: =IF(AND(B31>0,B31<E31),B31-E31,0) -> 0 | H31: =IF(AND(B31=0,B31<E31),E31-B31,0) -> 0
A32: Footings & Foundation Labor | B32: 13649.38 | D32: =SUMIF(Material!$E:$E,TRIM(A32),Material!$F:$F) -> 15750 | E32: =SUM(C32:D32) -> 15750 | F32: =IF(AND(B32>0,B32>E32),B32-E32,0) -> 0 | G32: =IF(AND(B32>0,B32<E32),B32-E32,0) -> -2100.6195 | H32: =IF(AND(B32=0,B32<E32),E32-B32,0) -> 0
A33: Slab Prep - Material | B33: 435.372 | D33: =SUMIF(Material!$E:$E,TRIM(A33),Material!$F:$F) -> 0 | E33: =SUM(C33:D33) -> 0 | F33: =IF(AND(B33>0,B33>E33),B33-E33,0) -> 435.372 | G33: =IF(AND(B33>0,B33<E33),B33-E33,0) -> 0 | H33: =IF(AND(B33=0,B33<E33),E33-B33,0) -> 0
A34: Garage Concrete Slab | B34: 5040 | D34: =SUMIF(Material!$E:$E,TRIM(A34),Material!$F:$F) -> 4074.01 | E34: =SUM(C34:D34) -> 4074.01 | F34: =IF(AND(B34>0,B34>E34),B34-E34,0) -> 965.99 | G34: =IF(AND(B34>0,B34<E34),B34-E34,0) -> 0 | H34: =IF(AND(B34=0,B34<E34),E34-B34,0) -> 0
A35: Concrete Skim Coat Materials | B35: 6300 | D35: =SUMIF(Material!$E:$E,TRIM(A35),Material!$F:$F) -> 5354.94 | E35: =SUM(C35:D35) -> 5354.94 | F35: =IF(AND(B35>0,B35>E35),B35-E35,0) -> 945.06 | G35: =IF(AND(B35>0,B35<E35),B35-E35,0) -> 0 | H35: =IF(AND(B35=0,B35<E35),E35-B35,0) -> 0
A36: Garage Concrete Slab Finishing Labor | B36: 3620.925 | D36: =SUMIF(Material!$E:$E,TRIM(A36),Material!$F:$F) -> 0 | E36: =SUM(C36:D36) -> 0 | F36: =IF(AND(B36>0,B36>E36),B36-E36,0) -> 3620.925 | G36: =IF(AND(B36>0,B36<E36),B36-E36,0) -> 0 | H36: =IF(AND(B36=0,B36<E36),E36-B36,0) -> 0
A37: Concrete Pump Truck | B37: 3780 | D37: =SUMIF(Material!$E:$E,TRIM(A37),Material!$F:$F) -> 3664.42 | E37: =SUM(C37:D37) -> 3664.42 | F37: =IF(AND(B37>0,B37>E37),B37-E37,0) -> 115.58 | G37: =IF(AND(B37>0,B37<E37),B37-E37,0) -> 0 | H37: =IF(AND(B37=0,B37<E37),E37-B37,0) -> 0
A38: Damproofing | B38: 10500 | D38: =SUMIF(Material!$E:$E,TRIM(A38),Material!$F:$F) -> 3379.95 | E38: =SUM(C38:D38) -> 3379.95 | F38: =IF(AND(B38>0,B38>E38),B38-E38,0) -> 7120.05 | G38: =IF(AND(B38>0,B38<E38),B38-E38,0) -> 0 | H38: =IF(AND(B38=0,B38<E38),E38-B38,0) -> 0
A39: FOUNDATION — Subtotal | B39: =SUM(B30:B38) -> 80063.214 | C39: =SUM(C30:C38) -> 0 | D39: =SUM(D30:D38) -> 72023.76 | E39: =SUM(E30:E38) -> 72023.76 | F39: =SUM(F30:F38) -> 17793.197 | G39: =SUM(G30:G38) -> -9753.743 | H39: =SUM(H30:H38) -> 0
A41: FRAMING
A42: Framing Materials Cost | B42: 41235.086 | D42: =SUMIF(Material!$E:$E,TRIM(A42),Material!$F:$F) -> 59647.01 | E42: =SUM(C42:D42) -> 59647.01 | F42: =IF(AND(B42>0,B42>E42),B42-E42,0) -> 0 | G42: =IF(AND(B42>0,B42<E42),B42-E42,0) -> -18411.925 | H42: =IF(AND(B42=0,B42<E42),E42-B42,0) -> 0
A43: Roof Trusses | B43: 45150 | D43: =SUMIF(Material!$E:$E,TRIM(A43),Material!$F:$F) -> 43603.7 | E43: =SUM(C43:D43) -> 43603.7 | F43: =IF(AND(B43>0,B43>E43),B43-E43,0) -> 1546.3 | G43: =IF(AND(B43>0,B43<E43),B43-E43,0) -> 0 | H43: =IF(AND(B43=0,B43<E43),E43-B43,0) -> 0
A44: Floor System | B44: 14275.684 | D44: =SUMIF(Material!$E:$E,TRIM(A44),Material!$F:$F) -> 12383 | E44: =SUM(C44:D44) -> 12383 | F44: =IF(AND(B44>0,B44>E44),B44-E44,0) -> 1892.6845 | G44: =IF(AND(B44>0,B44<E44),B44-E44,0) -> 0 | H44: =IF(AND(B44=0,B44<E44),E44-B44,0) -> 0
A45: Engineering Hardware | B45: 11718.22 | D45: =SUMIF(Material!$E:$E,TRIM(A45),Material!$F:$F) -> 0 | E45: =SUM(C45:D45) -> 0 | F45: =IF(AND(B45>0,B45>E45),B45-E45,0) -> 11718.22 | G45: =IF(AND(B45>0,B45<E45),B45-E45,0) -> 0 | H45: =IF(AND(B45=0,B45<E45),E45-B45,0) -> 0
A46: Extra | B46: 5250 | D46: =SUMIF(Material!$E:$E,TRIM(A46),Material!$F:$F) -> 0 | E46: =SUM(C46:D46) -> 0 | F46: =IF(AND(B46>0,B46>E46),B46-E46,0) -> 5250 | G46: =IF(AND(B46>0,B46<E46),B46-E46,0) -> 0 | H46: =IF(AND(B46=0,B46<E46),E46-B46,0) -> 0
A47: FRAMING — Subtotal | B47: =SUM(B42:B46) -> 117628.99 | C47: =SUM(C42:C46) -> 0 | D47: =SUM(D42:D46) -> 115633.71 | E47: =SUM(E42:E46) -> 115633.71 | F47: =SUM(F42:F46) -> 20407.205 | G47: =SUM(G42:G46) -> -18411.925 | H47: =SUM(H42:H46) -> 0
...

Sheet Timesheet
A2: LINE ITEM | B2: Date | C2: Name | D2: Billing Status | E2: Duration
A3: 04 Site Work:Excavation,Backfill,Perimeter &
B4: 46070 | C4: Fielding K Benton | D4: Unbilled | E4: 4
B5: 46070 | C5: Fielding K Benton | D5: Unbilled | E5: 4
B6: 46071 | C6: Fielding K Benton | D6: Unbilled | E6: 4.5
B7: 46071 | C7: Fielding K Benton | D7: Unbilled | E7: 0.67
B8: 46072 | C8: Fielding K Benton | D8: Unbilled | E8: 2.17
B9: 46072 | C9: Fielding K Benton | D9: Unbilled | E9: 0.33
B10: 46073 | C10: Fielding K Benton | D10: Unbilled | E10: 3.83
B11: 46076 | C11: Fielding K Benton | D11: Unbilled | E11: 0.5
B12: 46080 | C12: Fielding K Benton | D12: Unbilled | E12: 5.17
B13: 46080 | C13: Fielding K Benton | D13: Unbilled | E13: 2.83
B14: 46083 | C14: Fielding K Benton | D14: Unbilled | E14: 3.5
B15: 46084 | C15: Fielding K Benton | D15: Unbilled | E15: 0.83
... B25: 46087 | C25: Fielding K Benton | D25: Unbilled | E25: 0.33
A26: Total 04 Site Work:Excavation,Backfill,Perimeter & | E26: 56.24
A27: 05 Foundation:Footings & Foundation Labor
B28: 46076 | C28: Fielding K Benton | D28: Unbilled | E28: 3.83
B29: 46076 | C29: Fielding K Benton | D29: Unbilled | E29: 0.5
B30: 46077 | C30: Fielding K Benton | D30: Unbilled | E30: 4.17
B31: 46078 | C31: Fielding K Benton | D31: Unbilled | E31: 0.17
B32: 46078 | C32: Fielding K Benton | D32: Unbilled | E32: 2.33
B33: 46079 | C33: Alaa Kadah | D33: Unbilled | E33: 3.67
B34: 46083 | C34: Fielding K Benton | D34: Unbilled | E34: 2.67
B35: 46090 | C35: Alaa Kadah | D35: Unbilled | E35: 2.83
B36: 46090 | C36: Alaa Kadah | D36: Unbilled | E36: 4.17
B37: 46090 | C37: Fielding K Benton | D37: Unbilled | E37: 6.17
B38: 46090 | C38: Fielding K Benton | D38: Unbilled | E38: 2.83
B39: 46091 | C39: Alaa Kadah | D39: Unbilled | E39: 4
... B59: 46101 | C59: Fielding K Benton | D59: Unbilled | E59: 3.17
A60: Total 05 Foundation:Footings & Foundation Labor | E60: 90.44
A61: 05 Foundation:Slap Prep Labor
B62: 46198 | C62: Fielding K Benton | D62: Unbilled | E62: 1.25
B63: 46198 | C63: Fielding K Benton | D63: Unbilled | E63: 1.67
B64: 46203 | C64: Fielding K Benton | D64: Unbilled | E64: 0.17
A65: Total 05 Foundation:Slap Prep Labor | E65: 3.09
A66: 06 Framing:Framing Labor
B67: 46104 | C67: Aaron Maskill | D67: Unbilled | E67: 4
B68: 46104 | C68: Aaron Maskill | D68: Unbilled | E68: 3.75
B69: 46104 | C69: Fielding K Benton | D69: Unbilled | E69: 0.75
...

Sheet Material
B1: Type | C1: Date | D1: Num | E1: Memo | F1: Amount
A2: 1047335 B.C. LTD (dba Complete Damp Proof
B3: Bill | C3: 46086 | D3: 11452 | E3: Damproofing | F3: 3379.95
A4: Total 1047335 B.C. LTD (dba Complete Damp Proof | F4: =ROUND(SUM(F2:F3),5) -> 3379.95
A5: ABC Supply and Co
B6: Credit Card Charge | C6: 46176 | E6: Roofing Supply & Install | F6: 2295.86
B7: Credit Card Credit | C7: 46183 | E7: Roofing Supply & Install | F7: -492.1
B8: Credit Card Charge | C8: 46203 | D8: 257305 | E8: Roofing Supply & Install | F8: 871.84
B9: Bill | C9: 46206 | D9: 319570 | E9: Roofing Supply & Install | F9: 4113.69
B10: Credit Card Credit | C10: 46206 | E10: Roofing Supply & Install | F10: -336.46
A11: Total ABC Supply and Co | F11: =ROUND(SUM(F5:F10),5) -> 6452.83
A12: Andrew Sheret Ltd
B13: Bill | C13: 46080 | D13: 03-084405 | E13: Backfill, Perimeter & Drain Material | F13: 411.09
B14: Bill | C14: 46083 | D14: 03-084596 | E14: Backfill, Perimeter & Drain Material | F14: 1162.28
B15: Bill | C15: 46088 | D15: 03-085259 | E15: Backfill, Perimeter & Drain Material | F15: 408.36
B16: Bill | C16: 46090 | D16: 03-085292 | E16: Backfill, Perimeter & Drain Material | F16: 227.04
B17: Bill | C17: 46091 | D17: 03-085458 | E17: Backfill, Perimeter & Drain Material | F17: 627.47
B18: Credit | C18: 46091 | D18: 03-085563 | E18: Backfill, Perimeter & Drain Material | F18: -255.26
B19: Bill | C19: 46093 | D19: 03-085864 | E19: Backfill, Perimeter & Drain Material | F19: 533.88
B20: Bill | C20: 46139 | D20: 03-090686 | E20: Backfill, Perimeter & Drain Material | F20: 797.73
B21: Bill | C21: 46154 | D21: 03-092447 | E21: Backfill, Perimeter & Drain Material | F21: 510.81
B22: Bill | C22: 46183 | D22: 03-095733 | E22: Backfill, Perimeter & Drain Material | F22: 7.66
B23: Bill | C23: 46185 | D23: 03-095751 | E23: Backfill, Perimeter & Drain Material | F23: 159.4
B24: Bill | C24: 46186 | D24: 03-096046 | E24: Backfill, Perimeter & Drain Material | F24: 58.29
... B30: Credit | C30: 46210 | D30: 03-096011 | E30: Backfill, Perimeter & Drain Material | F30: -6.07
A31: Total Andrew Sheret Ltd | F31: =ROUND(SUM(F12:F30),5) -> 12821.55
A32: BC Housing Licensing & Consumer Services
B33: Bill | C33: 46000 | D33: 875433 | E33: BC Housing Registration Fee | F33: 40
A34: Total BC Housing Licensing & Consumer Services | F34: =ROUND(SUM(F32:F33),5) -> 40
A35: BC Hydro
B36: Cheque | C36: 46203 | D36: Direct | E36: BC Hydro | F36: 4887.75
A37: Total BC Hydro | F37: =ROUND(SUM(F35:F36),5) -> 4887.75
A38: Bryan's Mechanical Ltd.
B39: Bill | C39: 46197 | D39: 696-D396-1 | E39: Mechanical Rough In & Finish | F39: 29581.13
A40: Total Bryan's Mechanical Ltd. | F40: =ROUND(SUM(F38:F39),5) -> 29581.13
A41: Chevron
B42: Credit Card Charge | C42: 46184 | E42: Framing Materials Cost | F42: 36.89
B43: Credit Card Charge | C43: 46190 | E43: Framing Materials Cost | F43: 47.34
B44: Credit Card Charge | C44: 46196 | E44: Framing Materials Cost | F44: 250
B45: Credit Card Charge | C45: 46216 | E45: Framing Materials Cost | F45: 250
...
